[ 2022-04-29T12:05:24     INFO ] logging to applications insights
[ 2022-04-29T12:05:25     INFO ] [ exists                   ] True
[ 2022-04-29T12:05:26     INFO ] [ get                      ] {'additional_properties': {}, 'id': '/subscriptions/b698965a-1f53-45ec-8b81-58458d1b25f7/resourceGroups/VMSSReImageRun1SOUTHCENTRALUS', 'name': 'VMSSReImageRun1SOUTHCENTRALUS', 'type': 'Microsoft.Resources/resourceGroups', 'properties': <azure.mgmt.resource.resources.v2021_04_01.models._models_py3.ResourceGroupProperties object at 0x7ffa219d6d00>, 'location': 'southcentralus', 'managed_by': None, 'tags': None}
[ 2022-04-29T12:05:27     INFO ] [ create                   ] {'additional_properties': {}, 'id': '/subscriptions/b698965a-1f53-45ec-8b81-58458d1b25f7/resourceGroups/VMSSReImageRun1SOUTHCENTRALUS/providers/Microsoft.Storage/storageAccounts/vmsspipeline9fc2a6bc', 'name': 'vmsspipeline9fc2a6bc', 'type': 'Microsoft.Storage/storageAccounts', 'tags': {'confidentiality': 'public'}, 'location': 'southcentralus', 'sku': <azure.mgmt.storage.v2021_09_01.models._models_py3.Sku object at 0x7ffa21812490>, 'kind': 'StorageV2', 'identity': None, 'extended_location': None, 'provisioning_state': 'Succeeded', 'primary_endpoints': <azure.mgmt.storage.v2021_09_01.models._models_py3.Endpoints object at 0x7ffa21812a30>, 'primary_location': 'southcentralus', 'status_of_primary': 'available', 'last_geo_failover_time': None, 'secondary_location': None, 'status_of_secondary': None, 'creation_time': datetime.datetime(2022, 4, 29, 16, 7, 7, 364576, tzinfo=<isodate.tzinfo.Utc object at 0x7ffa2551f5e0>), 'custom_domain': None, 'sas_policy': None, 'key_policy': None, 'key_creation_time': <azure.mgmt.storage.v2021_09_01.models._models_py3.KeyCreationTime object at 0x7ffa21812c40>, 'secondary_endpoints': None, 'encryption': <azure.mgmt.storage.v2021_09_01.models._models_py3.Encryption object at 0x7ffa21812a90>, 'access_tier': 'Hot', 'azure_files_identity_based_authentication': None, 'enable_https_traffic_only': True, 'network_rule_set': <azure.mgmt.storage.v2021_09_01.models._models_py3.NetworkRuleSet object at 0x7ffa21812be0>, 'is_sftp_enabled': None, 'is_local_user_enabled': None, 'is_hns_enabled': None, 'geo_replication_stats': None, 'failover_in_progress': None, 'large_file_shares_state': None, 'private_endpoint_connections': [], 'routing_preference': None, 'blob_restore_status': None, 'allow_blob_public_access': True, 'minimum_tls_version': 'TLS1_0', 'allow_shared_key_access': None, 'enable_nfs_v3': None, 'allow_cross_tenant_replication': None, 'default_to_o_auth_authentication': None, 'public_network_access': None, 'immutable_storage_with_versioning': None, 'allowed_copy_scope': None, 'storage_account_sku_conversion_status': None, 'dns_endpoint_type': None}
[ 2022-04-29T12:05:28     INFO ] [ get                      ] {'additional_properties': {}, 'id': '/subscriptions/b698965a-1f53-45ec-8b81-58458d1b25f7/resourceGroups/VMSSReImageRun1SOUTHCENTRALUS/providers/Microsoft.Network/networkSecurityGroups/vmssPeregrineTest-nsg', 'name': 'vmssPeregrineTest-nsg', 'type': 'Microsoft.Network/networkSecurityGroups', 'location': 'southcentralus', 'tags': {'confidentiality': 'public'}, 'etag': 'W/"eb7d1979-ed01-4960-a05c-263594cf31d5"', 'security_rules': [<azure.mgmt.network.v2021_05_01.models._models_py3.SecurityRule object at 0x7ffa21158a60>], 'default_security_rules': [<azure.mgmt.network.v2021_05_01.models._models_py3.SecurityRule object at 0x7ffa21158970>, <azure.mgmt.network.v2021_05_01.models._models_py3.SecurityRule object at 0x7ffa21158bb0>, <azure.mgmt.network.v2021_05_01.models._models_py3.SecurityRule object at 0x7ffa21158be0>, <azure.mgmt.network.v2021_05_01.models._models_py3.SecurityRule object at 0x7ffa21158c10>, <azure.mgmt.network.v2021_05_01.models._models_py3.SecurityRule object at 0x7ffa21158c40>, <azure.mgmt.network.v2021_05_01.models._models_py3.SecurityRule object at 0x7ffa21158c70>], 'network_interfaces': None, 'subnets': [<azure.mgmt.network.v2021_05_01.models._models_py3.Subnet object at 0x7ffa21158cd0>], 'flow_logs': None, 'resource_guid': 'a66db6d6-770c-4f59-9ac2-c283de4a9a24', 'provisioning_state': 'Succeeded'}
[ 2022-04-29T12:05:28     INFO ] [ get                      ] {'additional_properties': {}, 'id': '/subscriptions/b698965a-1f53-45ec-8b81-58458d1b25f7/resourceGroups/VMSSReImageRun1SOUTHCENTRALUS/providers/Microsoft.Network/virtualNetworks/vmssPeregrineTest-vnet', 'name': 'vmssPeregrineTest-vnet', 'type': 'Microsoft.Network/virtualNetworks', 'location': 'southcentralus', 'tags': {'confidentiality': 'public'}, 'extended_location': None, 'etag': 'W/"d5b4eb7c-ea37-462b-9ea4-fbd232834c2c"', 'address_space': <azure.mgmt.network.v2021_05_01.models._models_py3.AddressSpace object at 0x7ffa21158e20>, 'dhcp_options': None, 'flow_timeout_in_minutes': None, 'subnets': [<azure.mgmt.network.v2021_05_01.models._models_py3.Subnet object at 0x7ffa21812e20>], 'virtual_network_peerings': [], 'resource_guid': '0f1294d0-ba81-42f8-bd75-de499de66b2f', 'provisioning_state': 'Succeeded', 'enable_ddos_protection': False, 'enable_vm_protection': None, 'ddos_protection_plan': None, 'bgp_communities': None, 'encryption': None, 'ip_allocations': None}
[ 2022-04-29T12:05:28     INFO ] [ subnets_list             ] <iterator object azure.core.paging.ItemPaged at 0x7ffa21812ee0>
[ 2022-04-29T12:05:30     INFO ] [ get                      ] {'additional_properties': {}, 'id': '/subscriptions/b698965a-1f53-45ec-8b81-58458d1b25f7/resourceGroups/VMSSReImageRun1SOUTHCENTRALUS/providers/Microsoft.Compute/virtualMachineScaleSets/vmssPeregrineTest', 'name': 'vmssPeregrineTest', 'type': 'Microsoft.Compute/virtualMachineScaleSets', 'location': 'southcentralus', 'tags': {'confidentiality': 'public'}, 'sku': <azure.mgmt.compute.v2021_11_01.models._models_py3.Sku object at 0x7ffa20ecb760>, 'plan': None, 'identity': None, 'zones': ['1'], 'extended_location': None, 'upgrade_policy': None, 'automatic_repairs_policy': None, 'virtual_machine_profile': <azure.mgmt.compute.v2021_11_01.models._models_py3.VirtualMachineScaleSetVMProfile object at 0x7ffa20ecbc70>, 'provisioning_state': 'Succeeded', 'overprovision': None, 'do_not_run_extensions_on_overprovisioned_v_ms': None, 'unique_id': '37746c0b-92b4-4b45-961f-474922163bb5', 'single_placement_group': False, 'zone_balance': None, 'platform_fault_domain_count': 1, 'proximity_placement_group': None, 'host_group': None, 'additional_capabilities': None, 'scale_in_policy': None, 'orchestration_mode': 'Flexible', 'spot_restore_policy': None, 'time_created': datetime.datetime(2022, 4, 29, 16, 7, 45, 135353, tzinfo=<FixedOffset '+00:00'>)}
[ 2022-04-29T12:05:30     INFO ] [ get_vms                  ] <iterator object azure.core.paging.ItemPaged at 0x7ffa2118e130>
[ 2022-04-29T12:05:30    DEBUG ] Using selector: EpollSelector
[ 2022-04-29T12:05:30     INFO ] [ get_vms                  ] <iterator object azure.core.paging.ItemPaged at 0x7ffa20e599d0>
[ 2022-04-29T12:05:30     INFO ] Finish queuing all vms
[ 2022-04-29T12:05:31     INFO ] [ get                      ] {'additional_properties': {}, 'platform_update_domain': None, 'platform_fault_domain': None, 'computer_name': 'vmInstance1OE4NY', 'os_name': 'ubuntu', 'os_version': '18.04', 'hyper_v_generation': 'V1', 'rdp_thumb_print': None, 'vm_agent': <azure.mgmt.compute.v2021_11_01.models._models_py3.VirtualMachineAgentInstanceView object at 0x7ffa20e86d00>, 'maintenance_redeploy_status': None, 'disks': [<azure.mgmt.compute.v2021_11_01.models._models_py3.DiskInstanceView object at 0x7ffa20e86ee0>], 'extensions': [], 'vm_health': None, 'boot_diagnostics': <azure.mgmt.compute.v2021_11_01.models._models_py3.BootDiagnosticsInstanceView object at 0x7ffa20e86d90>, 'assigned_host': None, 'statuses': [<azure.mgmt.compute.v2021_11_01.models._models_py3.InstanceViewStatus object at 0x7ffa20e8a070>, <azure.mgmt.compute.v2021_11_01.models._models_py3.InstanceViewStatus object at 0x7ffa20e8a0a0>], 'patch_status': None}
[ 2022-04-29T12:05:32     INFO ] [ get                      ] {'additional_properties': {}, 'platform_update_domain': None, 'platform_fault_domain': None, 'computer_name': 'vmInstance1ZB63N', 'os_name': 'ubuntu', 'os_version': '18.04', 'hyper_v_generation': 'V1', 'rdp_thumb_print': None, 'vm_agent': <azure.mgmt.compute.v2021_11_01.models._models_py3.VirtualMachineAgentInstanceView object at 0x7ffa2006efd0>, 'maintenance_redeploy_status': None, 'disks': [<azure.mgmt.compute.v2021_11_01.models._models_py3.DiskInstanceView object at 0x7ffa2007b250>], 'extensions': [], 'vm_health': None, 'boot_diagnostics': <azure.mgmt.compute.v2021_11_01.models._models_py3.BootDiagnosticsInstanceView object at 0x7ffa2007b100>, 'assigned_host': None, 'statuses': [<azure.mgmt.compute.v2021_11_01.models._models_py3.InstanceViewStatus object at 0x7ffa2007b3a0>, <azure.mgmt.compute.v2021_11_01.models._models_py3.InstanceViewStatus object at 0x7ffa2007b3d0>], 'patch_status': None}
[ 2022-04-29T12:05:32     INFO ] [ get                      ] {'additional_properties': {}, 'platform_update_domain': None, 'platform_fault_domain': None, 'computer_name': 'vmInstance2C0PSP', 'os_name': 'ubuntu', 'os_version': '18.04', 'hyper_v_generation': 'V1', 'rdp_thumb_print': None, 'vm_agent': <azure.mgmt.compute.v2021_11_01.models._models_py3.VirtualMachineAgentInstanceView object at 0x7ffa20082490>, 'maintenance_redeploy_status': None, 'disks': [<azure.mgmt.compute.v2021_11_01.models._models_py3.DiskInstanceView object at 0x7ffa20082670>], 'extensions': [], 'vm_health': None, 'boot_diagnostics': <azure.mgmt.compute.v2021_11_01.models._models_py3.BootDiagnosticsInstanceView object at 0x7ffa20082520>, 'assigned_host': None, 'statuses': [<azure.mgmt.compute.v2021_11_01.models._models_py3.InstanceViewStatus object at 0x7ffa200827c0>, <azure.mgmt.compute.v2021_11_01.models._models_py3.InstanceViewStatus object at 0x7ffa200827f0>], 'patch_status': None}
[ 2022-04-29T12:05:33     INFO ] [ get                      ] {'additional_properties': {}, 'platform_update_domain': None, 'platform_fault_domain': None, 'computer_name': 'vmInstance2RNIEP', 'os_name': 'ubuntu', 'os_version': '18.04', 'hyper_v_generation': 'V1', 'rdp_thumb_print': None, 'vm_agent': <azure.mgmt.compute.v2021_11_01.models._models_py3.VirtualMachineAgentInstanceView object at 0x7ffa20071a30>, 'maintenance_redeploy_status': None, 'disks': [<azure.mgmt.compute.v2021_11_01.models._models_py3.DiskInstanceView object at 0x7ffa20071c10>], 'extensions': [], 'vm_health': None, 'boot_diagnostics': <azure.mgmt.compute.v2021_11_01.models._models_py3.BootDiagnosticsInstanceView object at 0x7ffa200719d0>, 'assigned_host': None, 'statuses': [<azure.mgmt.compute.v2021_11_01.models._models_py3.InstanceViewStatus object at 0x7ffa20071d90>, <azure.mgmt.compute.v2021_11_01.models._models_py3.InstanceViewStatus object at 0x7ffa20071dc0>], 'patch_status': None}
[ 2022-04-29T12:05:33     INFO ] [ get                      ] {'additional_properties': {}, 'platform_update_domain': None, 'platform_fault_domain': None, 'computer_name': 'vmInstance2UT10B', 'os_name': 'ubuntu', 'os_version': '18.04', 'hyper_v_generation': 'V1', 'rdp_thumb_print': None, 'vm_agent': <azure.mgmt.compute.v2021_11_01.models._models_py3.VirtualMachineAgentInstanceView object at 0x7ffa20091fd0>, 'maintenance_redeploy_status': None, 'disks': [<azure.mgmt.compute.v2021_11_01.models._models_py3.DiskInstanceView object at 0x7ffa2007b790>], 'extensions': [], 'vm_health': None, 'boot_diagnostics': <azure.mgmt.compute.v2021_11_01.models._models_py3.BootDiagnosticsInstanceView object at 0x7ffa20082ee0>, 'assigned_host': None, 'statuses': [<azure.mgmt.compute.v2021_11_01.models._models_py3.InstanceViewStatus object at 0x7ffa2001b1f0>, <azure.mgmt.compute.v2021_11_01.models._models_py3.InstanceViewStatus object at 0x7ffa2001b220>], 'patch_status': None}
[ 2022-04-29T12:05:34     INFO ] [ get                      ] {'additional_properties': {}, 'platform_update_domain': None, 'platform_fault_domain': None, 'computer_name': 'vmInstance3BVHI3', 'os_name': 'ubuntu', 'os_version': '18.04', 'hyper_v_generation': 'V1', 'rdp_thumb_print': None, 'vm_agent': <azure.mgmt.compute.v2021_11_01.models._models_py3.VirtualMachineAgentInstanceView object at 0x7ffa20021dc0>, 'maintenance_redeploy_status': None, 'disks': [<azure.mgmt.compute.v2021_11_01.models._models_py3.DiskInstanceView object at 0x7ffa20021fa0>], 'extensions': [], 'vm_health': None, 'boot_diagnostics': <azure.mgmt.compute.v2021_11_01.models._models_py3.BootDiagnosticsInstanceView object at 0x7ffa20021e50>, 'assigned_host': None, 'statuses': [<azure.mgmt.compute.v2021_11_01.models._models_py3.InstanceViewStatus object at 0x7ffa20031130>, <azure.mgmt.compute.v2021_11_01.models._models_py3.InstanceViewStatus object at 0x7ffa20031160>], 'patch_status': None}
[ 2022-04-29T12:05:34     INFO ] [ get                      ] {'additional_properties': {}, 'platform_update_domain': None, 'platform_fault_domain': None, 'computer_name': 'vmInstance3NM16Y', 'os_name': 'ubuntu', 'os_version': '18.04', 'hyper_v_generation': 'V1', 'rdp_thumb_print': None, 'vm_agent': <azure.mgmt.compute.v2021_11_01.models._models_py3.VirtualMachineAgentInstanceView object at 0x7ffa20036250>, 'maintenance_redeploy_status': None, 'disks': [<azure.mgmt.compute.v2021_11_01.models._models_py3.DiskInstanceView object at 0x7ffa20036430>], 'extensions': [], 'vm_health': None, 'boot_diagnostics': <azure.mgmt.compute.v2021_11_01.models._models_py3.BootDiagnosticsInstanceView object at 0x7ffa200362e0>, 'assigned_host': None, 'statuses': [<azure.mgmt.compute.v2021_11_01.models._models_py3.InstanceViewStatus object at 0x7ffa20036580>, <azure.mgmt.compute.v2021_11_01.models._models_py3.InstanceViewStatus object at 0x7ffa200365b0>], 'patch_status': None}
[ 2022-04-29T12:05:35     INFO ] [ get                      ] {'additional_properties': {}, 'platform_update_domain': None, 'platform_fault_domain': None, 'computer_name': 'vmInstance46BHVP', 'os_name': 'ubuntu', 'os_version': '18.04', 'hyper_v_generation': 'V1', 'rdp_thumb_print': None, 'vm_agent': <azure.mgmt.compute.v2021_11_01.models._models_py3.VirtualMachineAgentInstanceView object at 0x7ffa2003e7f0>, 'maintenance_redeploy_status': None, 'disks': [<azure.mgmt.compute.v2021_11_01.models._models_py3.DiskInstanceView object at 0x7ffa2003e9d0>], 'extensions': [], 'vm_health': None, 'boot_diagnostics': <azure.mgmt.compute.v2021_11_01.models._models_py3.BootDiagnosticsInstanceView object at 0x7ffa2003e880>, 'assigned_host': None, 'statuses': [<azure.mgmt.compute.v2021_11_01.models._models_py3.InstanceViewStatus object at 0x7ffa2003eb20>, <azure.mgmt.compute.v2021_11_01.models._models_py3.InstanceViewStatus object at 0x7ffa2003eb50>], 'patch_status': None}
[ 2022-04-29T12:05:36     INFO ] [ get                      ] {'additional_properties': {}, 'platform_update_domain': None, 'platform_fault_domain': None, 'computer_name': 'vmInstance4MZ3H7', 'os_name': 'ubuntu', 'os_version': '18.04', 'hyper_v_generation': 'V1', 'rdp_thumb_print': None, 'vm_agent': <azure.mgmt.compute.v2021_11_01.models._models_py3.VirtualMachineAgentInstanceView object at 0x7ffa20045b50>, 'maintenance_redeploy_status': None, 'disks': [<azure.mgmt.compute.v2021_11_01.models._models_py3.DiskInstanceView object at 0x7ffa20045d30>], 'extensions': [], 'vm_health': None, 'boot_diagnostics': <azure.mgmt.compute.v2021_11_01.models._models_py3.BootDiagnosticsInstanceView object at 0x7ffa20045be0>, 'assigned_host': None, 'statuses': [<azure.mgmt.compute.v2021_11_01.models._models_py3.InstanceViewStatus object at 0x7ffa20045e80>, <azure.mgmt.compute.v2021_11_01.models._models_py3.InstanceViewStatus object at 0x7ffa20045eb0>], 'patch_status': None}
[ 2022-04-29T12:05:36     INFO ] [ get                      ] {'additional_properties': {}, 'platform_update_domain': None, 'platform_fault_domain': None, 'computer_name': 'vmInstance4TUB0I', 'os_name': 'ubuntu', 'os_version': '18.04', 'hyper_v_generation': 'V1', 'rdp_thumb_print': None, 'vm_agent': <azure.mgmt.compute.v2021_11_01.models._models_py3.VirtualMachineAgentInstanceView object at 0x7ffa20057130>, 'maintenance_redeploy_status': None, 'disks': [<azure.mgmt.compute.v2021_11_01.models._models_py3.DiskInstanceView object at 0x7ffa20057310>], 'extensions': [], 'vm_health': None, 'boot_diagnostics': <azure.mgmt.compute.v2021_11_01.models._models_py3.BootDiagnosticsInstanceView object at 0x7ffa200571c0>, 'assigned_host': None, 'statuses': [<azure.mgmt.compute.v2021_11_01.models._models_py3.InstanceViewStatus object at 0x7ffa20057460>, <azure.mgmt.compute.v2021_11_01.models._models_py3.InstanceViewStatus object at 0x7ffa20057490>], 'patch_status': None}
[ 2022-04-29T12:05:37    DEBUG ] Encoding detection on empty bytes, assuming utf_8 intention.
[ 2022-04-29T12:05:37    DEBUG ] Encoding detection on empty bytes, assuming utf_8 intention.
[ 2022-04-29T12:05:37    DEBUG ] Encoding detection on empty bytes, assuming utf_8 intention.
[ 2022-04-29T12:05:37    DEBUG ] Encoding detection on empty bytes, assuming utf_8 intention.
[ 2022-04-29T12:05:37    DEBUG ] Encoding detection on empty bytes, assuming utf_8 intention.
[ 2022-04-29T12:05:37    DEBUG ] Encoding detection on empty bytes, assuming utf_8 intention.
[ 2022-04-29T12:05:37    DEBUG ] Encoding detection on empty bytes, assuming utf_8 intention.
[ 2022-04-29T12:05:37    DEBUG ] Encoding detection on empty bytes, assuming utf_8 intention.
[ 2022-04-29T12:05:37    DEBUG ] Encoding detection on empty bytes, assuming utf_8 intention.
[ 2022-04-29T12:05:37    DEBUG ] Encoding detection on empty bytes, assuming utf_8 intention.
[ 2022-04-29T12:05:44  WARNING ] Request time out. Ingestion may be backed up. Retrying.
[ 2022-04-29T12:06:16    ERROR ] Task exception was never retrieved
future: <Task finished name='Task-2' coro=<logging_worker() done, defined at /home/crodriguezde/experiments/reimage/imds.py:37> exception=NameError("name 'raw' is not defined")>
Traceback (most recent call last):
  File "/home/crodriguezde/experiments/reimage/imds.py", line 40, in logging_worker
    logger_retry(msg)
  File "/home/crodriguezde/experiments/reimage/venv/lib/python3.8/site-packages/backoff/_sync.py", line 94, in retry
    ret = target(*args, **kwargs)
  File "/home/crodriguezde/experiments/reimage/imds.py", line 34, in logger_retry
    utils.log_imds(imds)
  File "/home/crodriguezde/experiments/reimage/utils.py", line 22, in log_imds
    'custom_dimensions': raw
NameError: name 'raw' is not defined
[ 2022-04-29T12:06:16    ERROR ] Task exception was never retrieved
future: <Task finished name='Task-13' coro=<_get() done, defined at /home/crodriguezde/experiments/reimage/venv/lib/python3.8/site-packages/backoff/_async.py:118> exception=AttributeError("'dict' object has no attribute 'uuid'")>
Traceback (most recent call last):
  File "/home/crodriguezde/experiments/reimage/venv/lib/python3.8/site-packages/backoff/_async.py", line 133, in retry
    ret = await target(*args, **kwargs)
  File "/home/crodriguezde/experiments/reimage/imds.py", line 78, in _get
    imds.uuid = cli_args.uuid
AttributeError: 'dict' object has no attribute 'uuid'
[ 2022-04-29T12:06:16    ERROR ] Task exception was never retrieved
future: <Task finished name='Task-12' coro=<_get() done, defined at /home/crodriguezde/experiments/reimage/venv/lib/python3.8/site-packages/backoff/_async.py:118> exception=AttributeError("'dict' object has no attribute 'uuid'")>
Traceback (most recent call last):
  File "/home/crodriguezde/experiments/reimage/venv/lib/python3.8/site-packages/backoff/_async.py", line 133, in retry
    ret = await target(*args, **kwargs)
  File "/home/crodriguezde/experiments/reimage/imds.py", line 78, in _get
    imds.uuid = cli_args.uuid
AttributeError: 'dict' object has no attribute 'uuid'
[ 2022-04-29T12:06:16    ERROR ] Task exception was never retrieved
future: <Task finished name='Task-11' coro=<_get() done, defined at /home/crodriguezde/experiments/reimage/venv/lib/python3.8/site-packages/backoff/_async.py:118> exception=AttributeError("'dict' object has no attribute 'uuid'")>
Traceback (most recent call last):
  File "/home/crodriguezde/experiments/reimage/venv/lib/python3.8/site-packages/backoff/_async.py", line 133, in retry
    ret = await target(*args, **kwargs)
  File "/home/crodriguezde/experiments/reimage/imds.py", line 78, in _get
    imds.uuid = cli_args.uuid
AttributeError: 'dict' object has no attribute 'uuid'
[ 2022-04-29T12:06:16    ERROR ] Task exception was never retrieved
future: <Task finished name='Task-10' coro=<_get() done, defined at /home/crodriguezde/experiments/reimage/venv/lib/python3.8/site-packages/backoff/_async.py:118> exception=AttributeError("'dict' object has no attribute 'uuid'")>
Traceback (most recent call last):
  File "/home/crodriguezde/experiments/reimage/venv/lib/python3.8/site-packages/backoff/_async.py", line 133, in retry
    ret = await target(*args, **kwargs)
  File "/home/crodriguezde/experiments/reimage/imds.py", line 78, in _get
    imds.uuid = cli_args.uuid
AttributeError: 'dict' object has no attribute 'uuid'
[ 2022-04-29T12:06:16    ERROR ] Task exception was never retrieved
future: <Task finished name='Task-9' coro=<_get() done, defined at /home/crodriguezde/experiments/reimage/venv/lib/python3.8/site-packages/backoff/_async.py:118> exception=AttributeError("'dict' object has no attribute 'uuid'")>
Traceback (most recent call last):
  File "/home/crodriguezde/experiments/reimage/venv/lib/python3.8/site-packages/backoff/_async.py", line 133, in retry
    ret = await target(*args, **kwargs)
  File "/home/crodriguezde/experiments/reimage/imds.py", line 78, in _get
    imds.uuid = cli_args.uuid
AttributeError: 'dict' object has no attribute 'uuid'
[ 2022-04-29T12:06:16    ERROR ] Task exception was never retrieved
future: <Task finished name='Task-8' coro=<_get() done, defined at /home/crodriguezde/experiments/reimage/venv/lib/python3.8/site-packages/backoff/_async.py:118> exception=AttributeError("'dict' object has no attribute 'uuid'")>
Traceback (most recent call last):
  File "/home/crodriguezde/experiments/reimage/venv/lib/python3.8/site-packages/backoff/_async.py", line 133, in retry
    ret = await target(*args, **kwargs)
  File "/home/crodriguezde/experiments/reimage/imds.py", line 78, in _get
    imds.uuid = cli_args.uuid
AttributeError: 'dict' object has no attribute 'uuid'
[ 2022-04-29T12:06:16    ERROR ] Task exception was never retrieved
future: <Task finished name='Task-7' coro=<_get() done, defined at /home/crodriguezde/experiments/reimage/venv/lib/python3.8/site-packages/backoff/_async.py:118> exception=AttributeError("'dict' object has no attribute 'uuid'")>
Traceback (most recent call last):
  File "/home/crodriguezde/experiments/reimage/venv/lib/python3.8/site-packages/backoff/_async.py", line 133, in retry
    ret = await target(*args, **kwargs)
  File "/home/crodriguezde/experiments/reimage/imds.py", line 78, in _get
    imds.uuid = cli_args.uuid
AttributeError: 'dict' object has no attribute 'uuid'
[ 2022-04-29T12:06:16    ERROR ] Task exception was never retrieved
future: <Task finished name='Task-6' coro=<_get() done, defined at /home/crodriguezde/experiments/reimage/venv/lib/python3.8/site-packages/backoff/_async.py:118> exception=AttributeError("'dict' object has no attribute 'uuid'")>
Traceback (most recent call last):
  File "/home/crodriguezde/experiments/reimage/venv/lib/python3.8/site-packages/backoff/_async.py", line 133, in retry
    ret = await target(*args, **kwargs)
  File "/home/crodriguezde/experiments/reimage/imds.py", line 78, in _get
    imds.uuid = cli_args.uuid
AttributeError: 'dict' object has no attribute 'uuid'
[ 2022-04-29T12:06:16    ERROR ] Task exception was never retrieved
future: <Task finished name='Task-5' coro=<_get() done, defined at /home/crodriguezde/experiments/reimage/venv/lib/python3.8/site-packages/backoff/_async.py:118> exception=AttributeError("'dict' object has no attribute 'uuid'")>
Traceback (most recent call last):
  File "/home/crodriguezde/experiments/reimage/venv/lib/python3.8/site-packages/backoff/_async.py", line 133, in retry
    ret = await target(*args, **kwargs)
  File "/home/crodriguezde/experiments/reimage/imds.py", line 78, in _get
    imds.uuid = cli_args.uuid
AttributeError: 'dict' object has no attribute 'uuid'
[ 2022-04-29T12:06:16    ERROR ] Task exception was never retrieved
future: <Task finished name='Task-14' coro=<_get() done, defined at /home/crodriguezde/experiments/reimage/venv/lib/python3.8/site-packages/backoff/_async.py:118> exception=AttributeError("'dict' object has no attribute 'uuid'")>
Traceback (most recent call last):
  File "/home/crodriguezde/experiments/reimage/venv/lib/python3.8/site-packages/backoff/_async.py", line 133, in retry
    ret = await target(*args, **kwargs)
  File "/home/crodriguezde/experiments/reimage/imds.py", line 78, in _get
    imds.uuid = cli_args.uuid
AttributeError: 'dict' object has no attribute 'uuid'
[ 2022-04-29T12:06:16     INFO ] Exit per user request
[ 2022-04-29T12:06:17    ERROR ] Unclosed client session
client_session: <aiohttp.client.ClientSession object at 0x7ffa20045130>
[ 2022-04-29T12:06:17    ERROR ] Unclosed connector
connections: ['[(<aiohttp.client_proto.ResponseHandler object at 0x7ffa10f9de20>, 696689.394254145)]']
connector: <aiohttp.connector.TCPConnector object at 0x7ffa20045760>
[ 2022-04-29T12:06:17    ERROR ] Fatal error on SSL transport
protocol: <asyncio.sslproto.SSLProtocol object at 0x7ffa10fa63a0>
transport: <_SelectorSocketTransport closing fd=28>
Traceback (most recent call last):
  File "/usr/lib/python3.8/asyncio/selector_events.py", line 910, in write
    n = self._sock.send(data)
OSError: [Errno 9] Bad file descriptor

During handling of the above exception, another exception occurred:

Traceback (most recent call last):
  File "/usr/lib/python3.8/asyncio/sslproto.py", line 685, in _process_write_backlog
    self._transport.write(chunk)
  File "/usr/lib/python3.8/asyncio/selector_events.py", line 916, in write
    self._fatal_error(exc, 'Fatal write error on socket transport')
  File "/usr/lib/python3.8/asyncio/selector_events.py", line 711, in _fatal_error
    self._force_close(exc)
  File "/usr/lib/python3.8/asyncio/selector_events.py", line 723, in _force_close
    self._loop.call_soon(self._call_connection_lost, exc)
  File "/usr/lib/python3.8/asyncio/base_events.py", line 719, in call_soon
    self._check_closed()
  File "/usr/lib/python3.8/asyncio/base_events.py", line 508, in _check_closed
    raise RuntimeError('Event loop is closed')
RuntimeError: Event loop is closed
