[ 2022-04-29T12:08:28     INFO ] logging to applications insights
[ 2022-04-29T12:08:28     INFO ] [ exists                   ] True
[ 2022-04-29T12:08:29     INFO ] [ get                      ] {'additional_properties': {}, 'id': '/subscriptions/b698965a-1f53-45ec-8b81-58458d1b25f7/resourceGroups/VMSSReImageRun1SOUTHCENTRALUS', 'name': 'VMSSReImageRun1SOUTHCENTRALUS', 'type': 'Microsoft.Resources/resourceGroups', 'properties': <azure.mgmt.resource.resources.v2021_04_01.models._models_py3.ResourceGroupProperties object at 0x7fef5f7a3d00>, 'location': 'southcentralus', 'managed_by': None, 'tags': None}
[ 2022-04-29T12:08:30     INFO ] [ create                   ] {'additional_properties': {}, 'id': '/subscriptions/b698965a-1f53-45ec-8b81-58458d1b25f7/resourceGroups/VMSSReImageRun1SOUTHCENTRALUS/providers/Microsoft.Storage/storageAccounts/vmsspipeline9fc2a6bc', 'name': 'vmsspipeline9fc2a6bc', 'type': 'Microsoft.Storage/storageAccounts', 'tags': {'confidentiality': 'public'}, 'location': 'southcentralus', 'sku': <azure.mgmt.storage.v2021_09_01.models._models_py3.Sku object at 0x7fef5f5e1490>, 'kind': 'StorageV2', 'identity': None, 'extended_location': None, 'provisioning_state': 'Succeeded', 'primary_endpoints': <azure.mgmt.storage.v2021_09_01.models._models_py3.Endpoints object at 0x7fef5f5e1a30>, 'primary_location': 'southcentralus', 'status_of_primary': 'available', 'last_geo_failover_time': None, 'secondary_location': None, 'status_of_secondary': None, 'creation_time': datetime.datetime(2022, 4, 29, 16, 7, 7, 364576, tzinfo=<isodate.tzinfo.Utc object at 0x7fef6f2fc5e0>), 'custom_domain': None, 'sas_policy': None, 'key_policy': None, 'key_creation_time': <azure.mgmt.storage.v2021_09_01.models._models_py3.KeyCreationTime object at 0x7fef5f5e1c40>, 'secondary_endpoints': None, 'encryption': <azure.mgmt.storage.v2021_09_01.models._models_py3.Encryption object at 0x7fef5f5e1a90>, 'access_tier': 'Hot', 'azure_files_identity_based_authentication': None, 'enable_https_traffic_only': True, 'network_rule_set': <azure.mgmt.storage.v2021_09_01.models._models_py3.NetworkRuleSet object at 0x7fef5f5e1be0>, 'is_sftp_enabled': None, 'is_local_user_enabled': None, 'is_hns_enabled': None, 'geo_replication_stats': None, 'failover_in_progress': None, 'large_file_shares_state': None, 'private_endpoint_connections': [], 'routing_preference': None, 'blob_restore_status': None, 'allow_blob_public_access': True, 'minimum_tls_version': 'TLS1_0', 'allow_shared_key_access': None, 'enable_nfs_v3': None, 'allow_cross_tenant_replication': None, 'default_to_o_auth_authentication': None, 'public_network_access': None, 'immutable_storage_with_versioning': None, 'allowed_copy_scope': None, 'storage_account_sku_conversion_status': None, 'dns_endpoint_type': None}
[ 2022-04-29T12:08:31     INFO ] [ get                      ] {'additional_properties': {}, 'id': '/subscriptions/b698965a-1f53-45ec-8b81-58458d1b25f7/resourceGroups/VMSSReImageRun1SOUTHCENTRALUS/providers/Microsoft.Network/networkSecurityGroups/vmssPeregrineTest-nsg', 'name': 'vmssPeregrineTest-nsg', 'type': 'Microsoft.Network/networkSecurityGroups', 'location': 'southcentralus', 'tags': {'confidentiality': 'public'}, 'etag': 'W/"eb7d1979-ed01-4960-a05c-263594cf31d5"', 'security_rules': [<azure.mgmt.network.v2021_05_01.models._models_py3.SecurityRule object at 0x7fef5ef27a60>], 'default_security_rules': [<azure.mgmt.network.v2021_05_01.models._models_py3.SecurityRule object at 0x7fef5ef27970>, <azure.mgmt.network.v2021_05_01.models._models_py3.SecurityRule object at 0x7fef5ef27bb0>, <azure.mgmt.network.v2021_05_01.models._models_py3.SecurityRule object at 0x7fef5ef27be0>, <azure.mgmt.network.v2021_05_01.models._models_py3.SecurityRule object at 0x7fef5ef27c10>, <azure.mgmt.network.v2021_05_01.models._models_py3.SecurityRule object at 0x7fef5ef27c40>, <azure.mgmt.network.v2021_05_01.models._models_py3.SecurityRule object at 0x7fef5ef27c70>], 'network_interfaces': None, 'subnets': [<azure.mgmt.network.v2021_05_01.models._models_py3.Subnet object at 0x7fef5ef27cd0>], 'flow_logs': None, 'resource_guid': 'a66db6d6-770c-4f59-9ac2-c283de4a9a24', 'provisioning_state': 'Succeeded'}
[ 2022-04-29T12:08:32     INFO ] [ get                      ] {'additional_properties': {}, 'id': '/subscriptions/b698965a-1f53-45ec-8b81-58458d1b25f7/resourceGroups/VMSSReImageRun1SOUTHCENTRALUS/providers/Microsoft.Network/virtualNetworks/vmssPeregrineTest-vnet', 'name': 'vmssPeregrineTest-vnet', 'type': 'Microsoft.Network/virtualNetworks', 'location': 'southcentralus', 'tags': {'confidentiality': 'public'}, 'extended_location': None, 'etag': 'W/"d5b4eb7c-ea37-462b-9ea4-fbd232834c2c"', 'address_space': <azure.mgmt.network.v2021_05_01.models._models_py3.AddressSpace object at 0x7fef5ef27e20>, 'dhcp_options': None, 'flow_timeout_in_minutes': None, 'subnets': [<azure.mgmt.network.v2021_05_01.models._models_py3.Subnet object at 0x7fef5f5e1e20>], 'virtual_network_peerings': [], 'resource_guid': '0f1294d0-ba81-42f8-bd75-de499de66b2f', 'provisioning_state': 'Succeeded', 'enable_ddos_protection': False, 'enable_vm_protection': None, 'ddos_protection_plan': None, 'bgp_communities': None, 'encryption': None, 'ip_allocations': None}
[ 2022-04-29T12:08:32     INFO ] [ subnets_list             ] <iterator object azure.core.paging.ItemPaged at 0x7fef5f5e1ee0>
[ 2022-04-29T12:08:33     INFO ] [ get                      ] {'additional_properties': {}, 'id': '/subscriptions/b698965a-1f53-45ec-8b81-58458d1b25f7/resourceGroups/VMSSReImageRun1SOUTHCENTRALUS/providers/Microsoft.Compute/virtualMachineScaleSets/vmssPeregrineTest', 'name': 'vmssPeregrineTest', 'type': 'Microsoft.Compute/virtualMachineScaleSets', 'location': 'southcentralus', 'tags': {'confidentiality': 'public'}, 'sku': <azure.mgmt.compute.v2021_11_01.models._models_py3.Sku object at 0x7fef5ec9a760>, 'plan': None, 'identity': None, 'zones': ['1'], 'extended_location': None, 'upgrade_policy': None, 'automatic_repairs_policy': None, 'virtual_machine_profile': <azure.mgmt.compute.v2021_11_01.models._models_py3.VirtualMachineScaleSetVMProfile object at 0x7fef5ec9ac70>, 'provisioning_state': 'Succeeded', 'overprovision': None, 'do_not_run_extensions_on_overprovisioned_v_ms': None, 'unique_id': '37746c0b-92b4-4b45-961f-474922163bb5', 'single_placement_group': False, 'zone_balance': None, 'platform_fault_domain_count': 1, 'proximity_placement_group': None, 'host_group': None, 'additional_capabilities': None, 'scale_in_policy': None, 'orchestration_mode': 'Flexible', 'spot_restore_policy': None, 'time_created': datetime.datetime(2022, 4, 29, 16, 7, 45, 135353, tzinfo=<FixedOffset '+00:00'>)}
[ 2022-04-29T12:08:33     INFO ] [ get_vms                  ] <iterator object azure.core.paging.ItemPaged at 0x7fef5ef5d130>
[ 2022-04-29T12:08:33    DEBUG ] Using selector: EpollSelector
[ 2022-04-29T12:08:33     INFO ] [ get_vms                  ] <iterator object azure.core.paging.ItemPaged at 0x7fef5ec289d0>
[ 2022-04-29T12:08:34     INFO ] Finish queuing all vms
[ 2022-04-29T12:08:34     INFO ] [ get                      ] {'additional_properties': {}, 'platform_update_domain': None, 'platform_fault_domain': None, 'computer_name': 'vmInstance1OE4NY', 'os_name': 'ubuntu', 'os_version': '18.04', 'hyper_v_generation': 'V1', 'rdp_thumb_print': None, 'vm_agent': <azure.mgmt.compute.v2021_11_01.models._models_py3.VirtualMachineAgentInstanceView object at 0x7fef5ec3cd00>, 'maintenance_redeploy_status': None, 'disks': [<azure.mgmt.compute.v2021_11_01.models._models_py3.DiskInstanceView object at 0x7fef5ec3cee0>], 'extensions': [], 'vm_health': None, 'boot_diagnostics': <azure.mgmt.compute.v2021_11_01.models._models_py3.BootDiagnosticsInstanceView object at 0x7fef5ec3cd90>, 'assigned_host': None, 'statuses': [<azure.mgmt.compute.v2021_11_01.models._models_py3.InstanceViewStatus object at 0x7fef5ec58070>, <azure.mgmt.compute.v2021_11_01.models._models_py3.InstanceViewStatus object at 0x7fef5ec580a0>], 'patch_status': None}
[ 2022-04-29T12:08:35     INFO ] [ get                      ] {'additional_properties': {}, 'platform_update_domain': None, 'platform_fault_domain': None, 'computer_name': 'vmInstance1ZB63N', 'os_name': 'ubuntu', 'os_version': '18.04', 'hyper_v_generation': 'V1', 'rdp_thumb_print': None, 'vm_agent': <azure.mgmt.compute.v2021_11_01.models._models_py3.VirtualMachineAgentInstanceView object at 0x7fef5de49100>, 'maintenance_redeploy_status': None, 'disks': [<azure.mgmt.compute.v2021_11_01.models._models_py3.DiskInstanceView object at 0x7fef5de492e0>], 'extensions': [], 'vm_health': None, 'boot_diagnostics': <azure.mgmt.compute.v2021_11_01.models._models_py3.BootDiagnosticsInstanceView object at 0x7fef5de49190>, 'assigned_host': None, 'statuses': [<azure.mgmt.compute.v2021_11_01.models._models_py3.InstanceViewStatus object at 0x7fef5de49430>, <azure.mgmt.compute.v2021_11_01.models._models_py3.InstanceViewStatus object at 0x7fef5de49460>], 'patch_status': None}
[ 2022-04-29T12:08:36     INFO ] [ get                      ] {'additional_properties': {}, 'platform_update_domain': None, 'platform_fault_domain': None, 'computer_name': 'vmInstance2C0PSP', 'os_name': 'ubuntu', 'os_version': '18.04', 'hyper_v_generation': 'V1', 'rdp_thumb_print': None, 'vm_agent': <azure.mgmt.compute.v2021_11_01.models._models_py3.VirtualMachineAgentInstanceView object at 0x7fef5de4f520>, 'maintenance_redeploy_status': None, 'disks': [<azure.mgmt.compute.v2021_11_01.models._models_py3.DiskInstanceView object at 0x7fef5de4f700>], 'extensions': [], 'vm_health': None, 'boot_diagnostics': <azure.mgmt.compute.v2021_11_01.models._models_py3.BootDiagnosticsInstanceView object at 0x7fef5de4f5b0>, 'assigned_host': None, 'statuses': [<azure.mgmt.compute.v2021_11_01.models._models_py3.InstanceViewStatus object at 0x7fef5de4f850>, <azure.mgmt.compute.v2021_11_01.models._models_py3.InstanceViewStatus object at 0x7fef5de4f880>], 'patch_status': None}
[ 2022-04-29T12:08:36     INFO ] [ get                      ] {'additional_properties': {}, 'platform_update_domain': None, 'platform_fault_domain': None, 'computer_name': 'vmInstance2RNIEP', 'os_name': 'ubuntu', 'os_version': '18.04', 'hyper_v_generation': 'V1', 'rdp_thumb_print': None, 'vm_agent': <azure.mgmt.compute.v2021_11_01.models._models_py3.VirtualMachineAgentInstanceView object at 0x7fef5de3fac0>, 'maintenance_redeploy_status': None, 'disks': [<azure.mgmt.compute.v2021_11_01.models._models_py3.DiskInstanceView object at 0x7fef5de3fca0>], 'extensions': [], 'vm_health': None, 'boot_diagnostics': <azure.mgmt.compute.v2021_11_01.models._models_py3.BootDiagnosticsInstanceView object at 0x7fef5de3fa60>, 'assigned_host': None, 'statuses': [<azure.mgmt.compute.v2021_11_01.models._models_py3.InstanceViewStatus object at 0x7fef5de3fe20>, <azure.mgmt.compute.v2021_11_01.models._models_py3.InstanceViewStatus object at 0x7fef5de3fe50>], 'patch_status': None}
[ 2022-04-29T12:08:37     INFO ] [ get                      ] {'additional_properties': {}, 'platform_update_domain': None, 'platform_fault_domain': None, 'computer_name': 'vmInstance2UT10B', 'os_name': 'ubuntu', 'os_version': '18.04', 'hyper_v_generation': 'V1', 'rdp_thumb_print': None, 'vm_agent': <azure.mgmt.compute.v2021_11_01.models._models_py3.VirtualMachineAgentInstanceView object at 0x7fef5de4ff70>, 'maintenance_redeploy_status': None, 'disks': [<azure.mgmt.compute.v2021_11_01.models._models_py3.DiskInstanceView object at 0x7fef5d5e8130>], 'extensions': [], 'vm_health': None, 'boot_diagnostics': <azure.mgmt.compute.v2021_11_01.models._models_py3.BootDiagnosticsInstanceView object at 0x7fef5de49d00>, 'assigned_host': None, 'statuses': [<azure.mgmt.compute.v2021_11_01.models._models_py3.InstanceViewStatus object at 0x7fef5d5e8280>, <azure.mgmt.compute.v2021_11_01.models._models_py3.InstanceViewStatus object at 0x7fef5d5e82b0>], 'patch_status': None}
[ 2022-04-29T12:08:38     INFO ] [ get                      ] {'additional_properties': {}, 'platform_update_domain': None, 'platform_fault_domain': None, 'computer_name': 'vmInstance3BVHI3', 'os_name': 'ubuntu', 'os_version': '18.04', 'hyper_v_generation': 'V1', 'rdp_thumb_print': None, 'vm_agent': <azure.mgmt.compute.v2021_11_01.models._models_py3.VirtualMachineAgentInstanceView object at 0x7fef5d5f1eb0>, 'maintenance_redeploy_status': None, 'disks': [<azure.mgmt.compute.v2021_11_01.models._models_py3.DiskInstanceView object at 0x7fef5d5fd0d0>], 'extensions': [], 'vm_health': None, 'boot_diagnostics': <azure.mgmt.compute.v2021_11_01.models._models_py3.BootDiagnosticsInstanceView object at 0x7fef5d5f1f40>, 'assigned_host': None, 'statuses': [<azure.mgmt.compute.v2021_11_01.models._models_py3.InstanceViewStatus object at 0x7fef5d5fd220>, <azure.mgmt.compute.v2021_11_01.models._models_py3.InstanceViewStatus object at 0x7fef5d5fd250>], 'patch_status': None}
[ 2022-04-29T12:08:38     INFO ] [ get                      ] {'additional_properties': {}, 'platform_update_domain': None, 'platform_fault_domain': None, 'computer_name': 'vmInstance3NM16Y', 'os_name': 'ubuntu', 'os_version': '18.04', 'hyper_v_generation': 'V1', 'rdp_thumb_print': None, 'vm_agent': <azure.mgmt.compute.v2021_11_01.models._models_py3.VirtualMachineAgentInstanceView object at 0x7fef5d5f1220>, 'maintenance_redeploy_status': None, 'disks': [<azure.mgmt.compute.v2021_11_01.models._models_py3.DiskInstanceView object at 0x7fef5d5f12e0>], 'extensions': [], 'vm_health': None, 'boot_diagnostics': <azure.mgmt.compute.v2021_11_01.models._models_py3.BootDiagnosticsInstanceView object at 0x7fef5d5f1700>, 'assigned_host': None, 'statuses': [<azure.mgmt.compute.v2021_11_01.models._models_py3.InstanceViewStatus object at 0x7fef5d5e8d00>, <azure.mgmt.compute.v2021_11_01.models._models_py3.InstanceViewStatus object at 0x7fef5d5e8f10>], 'patch_status': None}
[ 2022-04-29T12:08:39     INFO ] [ get                      ] {'additional_properties': {}, 'platform_update_domain': None, 'platform_fault_domain': None, 'computer_name': 'vmInstance46BHVP', 'os_name': 'ubuntu', 'os_version': '18.04', 'hyper_v_generation': 'V1', 'rdp_thumb_print': None, 'vm_agent': <azure.mgmt.compute.v2021_11_01.models._models_py3.VirtualMachineAgentInstanceView object at 0x7fef5d615eb0>, 'maintenance_redeploy_status': None, 'disks': [<azure.mgmt.compute.v2021_11_01.models._models_py3.DiskInstanceView object at 0x7fef5d6110d0>], 'extensions': [], 'vm_health': None, 'boot_diagnostics': <azure.mgmt.compute.v2021_11_01.models._models_py3.BootDiagnosticsInstanceView object at 0x7fef5d615f40>, 'assigned_host': None, 'statuses': [<azure.mgmt.compute.v2021_11_01.models._models_py3.InstanceViewStatus object at 0x7fef5d611220>, <azure.mgmt.compute.v2021_11_01.models._models_py3.InstanceViewStatus object at 0x7fef5d611250>], 'patch_status': None}
[ 2022-04-29T12:08:39     INFO ] [ get                      ] {'additional_properties': {}, 'platform_update_domain': None, 'platform_fault_domain': None, 'computer_name': 'vmInstance4MZ3H7', 'os_name': 'ubuntu', 'os_version': '18.04', 'hyper_v_generation': 'V1', 'rdp_thumb_print': None, 'vm_agent': <azure.mgmt.compute.v2021_11_01.models._models_py3.VirtualMachineAgentInstanceView object at 0x7fef5d5ee490>, 'maintenance_redeploy_status': None, 'disks': [<azure.mgmt.compute.v2021_11_01.models._models_py3.DiskInstanceView object at 0x7fef5d5ee670>], 'extensions': [], 'vm_health': None, 'boot_diagnostics': <azure.mgmt.compute.v2021_11_01.models._models_py3.BootDiagnosticsInstanceView object at 0x7fef5d5ee520>, 'assigned_host': None, 'statuses': [<azure.mgmt.compute.v2021_11_01.models._models_py3.InstanceViewStatus object at 0x7fef5d5ee7c0>, <azure.mgmt.compute.v2021_11_01.models._models_py3.InstanceViewStatus object at 0x7fef5d5ee7f0>], 'patch_status': None}
[ 2022-04-29T12:08:40     INFO ] [ get                      ] {'additional_properties': {}, 'platform_update_domain': None, 'platform_fault_domain': None, 'computer_name': 'vmInstance4TUB0I', 'os_name': 'ubuntu', 'os_version': '18.04', 'hyper_v_generation': 'V1', 'rdp_thumb_print': None, 'vm_agent': <azure.mgmt.compute.v2021_11_01.models._models_py3.VirtualMachineAgentInstanceView object at 0x7fef5d6066d0>, 'maintenance_redeploy_status': None, 'disks': [<azure.mgmt.compute.v2021_11_01.models._models_py3.DiskInstanceView object at 0x7fef5d6068b0>], 'extensions': [], 'vm_health': None, 'boot_diagnostics': <azure.mgmt.compute.v2021_11_01.models._models_py3.BootDiagnosticsInstanceView object at 0x7fef5d606760>, 'assigned_host': None, 'statuses': [<azure.mgmt.compute.v2021_11_01.models._models_py3.InstanceViewStatus object at 0x7fef5d606a00>, <azure.mgmt.compute.v2021_11_01.models._models_py3.InstanceViewStatus object at 0x7fef5d606a30>], 'patch_status': None}
[ 2022-04-29T12:08:40    DEBUG ] Encoding detection on empty bytes, assuming utf_8 intention.
[ 2022-04-29T12:08:40    DEBUG ] Encoding detection on empty bytes, assuming utf_8 intention.
[ 2022-04-29T12:08:40    DEBUG ] Encoding detection on empty bytes, assuming utf_8 intention.
[ 2022-04-29T12:08:40    DEBUG ] Encoding detection on empty bytes, assuming utf_8 intention.
[ 2022-04-29T12:08:40    DEBUG ] Encoding detection on empty bytes, assuming utf_8 intention.
[ 2022-04-29T12:08:40    DEBUG ] Encoding detection on empty bytes, assuming utf_8 intention.
[ 2022-04-29T12:08:40    DEBUG ] Encoding detection on empty bytes, assuming utf_8 intention.
[ 2022-04-29T12:08:40    DEBUG ] Encoding detection on empty bytes, assuming utf_8 intention.
[ 2022-04-29T12:08:40    DEBUG ] Encoding detection on empty bytes, assuming utf_8 intention.
[ 2022-04-29T12:08:41    DEBUG ] Encoding detection on empty bytes, assuming utf_8 intention.
[ 2022-04-29T12:10:06    ERROR ] Task exception was never retrieved
future: <Task finished name='Task-2' coro=<logging_worker() done, defined at /home/crodriguezde/experiments/reimage/imds.py:37> exception=NameError("name 'raw' is not defined")>
Traceback (most recent call last):
  File "/home/crodriguezde/experiments/reimage/imds.py", line 40, in logging_worker
    logger_retry(msg)
  File "/home/crodriguezde/experiments/reimage/venv/lib/python3.8/site-packages/backoff/_sync.py", line 94, in retry
    ret = target(*args, **kwargs)
  File "/home/crodriguezde/experiments/reimage/imds.py", line 34, in logger_retry
    utils.log_imds(imds)
  File "/home/crodriguezde/experiments/reimage/utils.py", line 22, in log_imds
    'custom_dimensions': raw
NameError: name 'raw' is not defined
[ 2022-04-29T12:10:06    ERROR ] Task exception was never retrieved
future: <Task finished name='Task-13' coro=<_get() done, defined at /home/crodriguezde/experiments/reimage/venv/lib/python3.8/site-packages/backoff/_async.py:118> exception=AttributeError("'dict' object has no attribute 'uuid'")>
Traceback (most recent call last):
  File "/home/crodriguezde/experiments/reimage/venv/lib/python3.8/site-packages/backoff/_async.py", line 133, in retry
    ret = await target(*args, **kwargs)
  File "/home/crodriguezde/experiments/reimage/imds.py", line 79, in _get
    imds.uuid = cli_args.uuid
AttributeError: 'dict' object has no attribute 'uuid'
[ 2022-04-29T12:10:06    ERROR ] Task exception was never retrieved
future: <Task finished name='Task-12' coro=<_get() done, defined at /home/crodriguezde/experiments/reimage/venv/lib/python3.8/site-packages/backoff/_async.py:118> exception=AttributeError("'dict' object has no attribute 'uuid'")>
Traceback (most recent call last):
  File "/home/crodriguezde/experiments/reimage/venv/lib/python3.8/site-packages/backoff/_async.py", line 133, in retry
    ret = await target(*args, **kwargs)
  File "/home/crodriguezde/experiments/reimage/imds.py", line 79, in _get
    imds.uuid = cli_args.uuid
AttributeError: 'dict' object has no attribute 'uuid'
[ 2022-04-29T12:10:06    ERROR ] Task exception was never retrieved
future: <Task finished name='Task-11' coro=<_get() done, defined at /home/crodriguezde/experiments/reimage/venv/lib/python3.8/site-packages/backoff/_async.py:118> exception=AttributeError("'dict' object has no attribute 'uuid'")>
Traceback (most recent call last):
  File "/home/crodriguezde/experiments/reimage/venv/lib/python3.8/site-packages/backoff/_async.py", line 133, in retry
    ret = await target(*args, **kwargs)
  File "/home/crodriguezde/experiments/reimage/imds.py", line 79, in _get
    imds.uuid = cli_args.uuid
AttributeError: 'dict' object has no attribute 'uuid'
[ 2022-04-29T12:10:06    ERROR ] Task exception was never retrieved
future: <Task finished name='Task-10' coro=<_get() done, defined at /home/crodriguezde/experiments/reimage/venv/lib/python3.8/site-packages/backoff/_async.py:118> exception=AttributeError("'dict' object has no attribute 'uuid'")>
Traceback (most recent call last):
  File "/home/crodriguezde/experiments/reimage/venv/lib/python3.8/site-packages/backoff/_async.py", line 133, in retry
    ret = await target(*args, **kwargs)
  File "/home/crodriguezde/experiments/reimage/imds.py", line 79, in _get
    imds.uuid = cli_args.uuid
AttributeError: 'dict' object has no attribute 'uuid'
[ 2022-04-29T12:10:06    ERROR ] Task exception was never retrieved
future: <Task finished name='Task-9' coro=<_get() done, defined at /home/crodriguezde/experiments/reimage/venv/lib/python3.8/site-packages/backoff/_async.py:118> exception=AttributeError("'dict' object has no attribute 'uuid'")>
Traceback (most recent call last):
  File "/home/crodriguezde/experiments/reimage/venv/lib/python3.8/site-packages/backoff/_async.py", line 133, in retry
    ret = await target(*args, **kwargs)
  File "/home/crodriguezde/experiments/reimage/imds.py", line 79, in _get
    imds.uuid = cli_args.uuid
AttributeError: 'dict' object has no attribute 'uuid'
[ 2022-04-29T12:10:06    ERROR ] Task exception was never retrieved
future: <Task finished name='Task-8' coro=<_get() done, defined at /home/crodriguezde/experiments/reimage/venv/lib/python3.8/site-packages/backoff/_async.py:118> exception=AttributeError("'dict' object has no attribute 'uuid'")>
Traceback (most recent call last):
  File "/home/crodriguezde/experiments/reimage/venv/lib/python3.8/site-packages/backoff/_async.py", line 133, in retry
    ret = await target(*args, **kwargs)
  File "/home/crodriguezde/experiments/reimage/imds.py", line 79, in _get
    imds.uuid = cli_args.uuid
AttributeError: 'dict' object has no attribute 'uuid'
[ 2022-04-29T12:10:06    ERROR ] Task exception was never retrieved
future: <Task finished name='Task-7' coro=<_get() done, defined at /home/crodriguezde/experiments/reimage/venv/lib/python3.8/site-packages/backoff/_async.py:118> exception=AttributeError("'dict' object has no attribute 'uuid'")>
Traceback (most recent call last):
  File "/home/crodriguezde/experiments/reimage/venv/lib/python3.8/site-packages/backoff/_async.py", line 133, in retry
    ret = await target(*args, **kwargs)
  File "/home/crodriguezde/experiments/reimage/imds.py", line 79, in _get
    imds.uuid = cli_args.uuid
AttributeError: 'dict' object has no attribute 'uuid'
[ 2022-04-29T12:10:06    ERROR ] Task exception was never retrieved
future: <Task finished name='Task-6' coro=<_get() done, defined at /home/crodriguezde/experiments/reimage/venv/lib/python3.8/site-packages/backoff/_async.py:118> exception=AttributeError("'dict' object has no attribute 'uuid'")>
Traceback (most recent call last):
  File "/home/crodriguezde/experiments/reimage/venv/lib/python3.8/site-packages/backoff/_async.py", line 133, in retry
    ret = await target(*args, **kwargs)
  File "/home/crodriguezde/experiments/reimage/imds.py", line 79, in _get
    imds.uuid = cli_args.uuid
AttributeError: 'dict' object has no attribute 'uuid'
[ 2022-04-29T12:10:06    ERROR ] Task exception was never retrieved
future: <Task finished name='Task-5' coro=<_get() done, defined at /home/crodriguezde/experiments/reimage/venv/lib/python3.8/site-packages/backoff/_async.py:118> exception=AttributeError("'dict' object has no attribute 'uuid'")>
Traceback (most recent call last):
  File "/home/crodriguezde/experiments/reimage/venv/lib/python3.8/site-packages/backoff/_async.py", line 133, in retry
    ret = await target(*args, **kwargs)
  File "/home/crodriguezde/experiments/reimage/imds.py", line 79, in _get
    imds.uuid = cli_args.uuid
AttributeError: 'dict' object has no attribute 'uuid'
[ 2022-04-29T12:10:06    ERROR ] Task exception was never retrieved
future: <Task finished name='Task-14' coro=<_get() done, defined at /home/crodriguezde/experiments/reimage/venv/lib/python3.8/site-packages/backoff/_async.py:118> exception=AttributeError("'dict' object has no attribute 'uuid'")>
Traceback (most recent call last):
  File "/home/crodriguezde/experiments/reimage/venv/lib/python3.8/site-packages/backoff/_async.py", line 133, in retry
    ret = await target(*args, **kwargs)
  File "/home/crodriguezde/experiments/reimage/imds.py", line 79, in _get
    imds.uuid = cli_args.uuid
AttributeError: 'dict' object has no attribute 'uuid'
[ 2022-04-29T12:10:06     INFO ] Exit per user request
[ 2022-04-29T12:10:06    ERROR ] Unclosed client session
client_session: <aiohttp.client.ClientSession object at 0x7fef5d5ee160>
[ 2022-04-29T12:10:06    ERROR ] Unclosed client session
client_session: <aiohttp.client.ClientSession object at 0x7fef5de2f5e0>
[ 2022-04-29T12:10:06    ERROR ] Unclosed client session
client_session: <aiohttp.client.ClientSession object at 0x7fef5de2f730>
